Workbook
Name Common: #REF!
Name Common_TI: #REF!
Name Dry_NGL_DD: #REF!
Name HP_Ex_TI: #REF!
Name PF_Exclusive: #REF!

Sheet Sale Summary
C3: Values
B4: Cat | C4: Sum of RF May- 26 | D4: Sum of Sales Qty | E4: Sum of Ready Stock | F4: Sum of Ready + transist
B5: DD | C5: 436307.4 | D5: 219036 | E5: 234396 | F5: 258348 | G5: =D5/C5 -> 0.5020222
B6: Ganache | C6: 252703.92 | D6: 141564 | E6: 282492 | F6: 297612 | G6: =D6/C6 -> 0.56019709
B7: NFL | C7: 4669.2 | D7: 2736 | E7: 5988 | F7: 5988 | G7: =D7/C7 -> 0.58596762
B8: NGL | C8: 86200.95 | D8: 50840 | E8: 113671 | F8: 121825 | G8: =D8/C8 -> 0.58978468
B9: T&I | C9: 5417188.4 | D9: 3107580 | E9: 3764366 | F9: 4484438 | G9: =D9/C9 -> 0.57365182 | H9: previus | I9: 3365905
B10: UHT-Chill | C10: 43052.04 | D10: 20928 | E10: 27480 | F10: 28294 | G10: =D10/C10 -> 0.48610937 | H10: yest | I10: 3542684 | J10: =I10-I9 -> 176779
B11: #N/A | C11: 0 | D11: 0 | E11: 1164 | F11: 1164 | G11: =D11/C11 -> #DIV/0!
B12: Grand Total | C12: 6240121.9 | D12: 3542684 | E12: 4429557 | F12: 5197669
B15: Cat | C15: RF May'26 | D15: MTD Sales Qty | E15: Ready Stock | F15: R+Tstock | G15: Sale % | H15: INV Cover (Ready Stock) | I15: INV Cover (R+T)
B16: DD | C16: =C5 -> 436307.4 | D16: =D5 -> 219036 | E16: =E5 -> 234396 | F16: =F5 -> 258348 | G16: =D16/C16 -> 0.5020222 | H16: =+E16/(C16/30) -> 16.116802 | I16: =+F16/(C16/30) -> 17.763714
B17: Ganache | C17: =C6 -> 252703.92 | D17: =D6 -> 141564 | E17: =E6 -> 282492 | F17: =F6 -> 297612 | G17: =D17/C17 -> 0.56019709 | H17: =+E17/(C17/30) -> 33.536322 | I17: =+F17/(C17/30) -> 35.331308
B18: NFL | C18: =C7 -> 4669.2 | D18: =D7 -> 2736 | E18: =E7 -> 5988 | F18: =F7 -> 5988 | G18: =D18/C18 -> 0.58596762 | H18: =+E18/(C18/30) -> 38.4734 | I18: =+F18/(C18/30) -> 38.4734
B19: NGL | C19: =C8 -> 86200.95 | D19: =D8 -> 50840 | E19: =E8 -> 113671 | F19: =F8 -> 121825 | G19: =D19/C19 -> 0.58978468 | H19: =+E19/(C19/30) -> 39.560237 | I19: =+F19/(C19/30) -> 42.398025
B20: T&I | C20: =C9 -> 5417188.4 | D20: =D9 -> 3107580 | E20: =E9 -> 3764366 | F20: =F9 -> 4484438 | G20: =D20/C20 -> 0.57365182 | H20: =+E20/(C20/30) -> 20.846788 | I20: =+F20/(C20/30) -> 24.834495
B21: UHT-Chill | C21: =C10 -> 43052.04 | D21: =D10 -> 20928 | E21: =E10 -> 27480 | F21: =F10 -> 28294 | G21: =D21/C21 -> 0.48610937 | H21: =+E21/(C21/30) -> 19.148918 | I21: =+F21/(C21/30) -> 19.716139
B22: Grand Total | C22: =SUM(C16:C21) -> 6240121.9 | D22: =SUM(D16:D21) -> 3542684 | E22: =SUM(E16:E21) -> 4428393 | F22: =SUM(F16:F21) -> 5196505 | G22: =D22/C22 -> 0.56772673 | H22: =+E22/(C22/30) -> 21.289935 | I22: =+F22/(C22/30) -> 24.982709
B23: In Transit | F23: =F22-E22 -> 768112

Sheet Category wise INV days
C1: =TODAY()-1 -> 46166
B2: Category | C2: RF May'26 | D2: Sale Qty | E2: Sale % to RF | G2: Ready Stock at HUB | H2: INV Days Ready Stock | J2: Ready + transist | K2: INV Days Reday + Transit Stock
B3: UHT Dry(DD+Varsatie) | C3: ='Sale Summary'!C16 -> 436307.4 | D3: ='Sale Summary'!D16 -> 219036 | E3: =D3/C3 -> 0.5020222 | G3: ='Sale Summary'!E16 -> 234396 | H3: =G3/(C3/30) -> 16.116802 | J3: ='Sale Summary'!F16 -> 258348 | K3: =J3/(C3/30) -> 17.763714
B4: Ganache | C4: ='Sale Summary'!C17 -> 252703.92 | D4: ='Sale Summary'!D17 -> 141564 | E4: =D4/C4 -> 0.56019709 | G4: ='Sale Summary'!E17 -> 282492 | H4: =G4/(C4/30) -> 33.536322 | J4: ='Sale Summary'!F17 -> 297612 | K4: =J4/(C4/30) -> 35.331308
B5: NFL | C5: ='Sale Summary'!C18 -> 4669.2 | D5: ='Sale Summary'!D18 -> 2736 | E5: =D5/C5 -> 0.58596762 | G5: ='Sale Summary'!E18 -> 5988 | H5: =G5/(C5/30) -> 38.4734 | J5: ='Sale Summary'!F18 -> 5988 | K5: =J5/(C5/30) -> 38.4734
B6: NGL | C6: ='Sale Summary'!C19 -> 86200.95 | D6: ='Sale Summary'!D19 -> 50840 | E6: =D6/C6 -> 0.58978468 | G6: ='Sale Summary'!E19 -> 113671 | H6: =G6/(C6/30) -> 39.560237 | J6: ='Sale Summary'!F19 -> 121825 | K6: =J6/(C6/30) -> 42.398025
B7: T&I | C7: ='Sale Summary'!C20 -> 5417188.4 | D7: ='Sale Summary'!D20 -> 3107580 | E7: =D7/C7 -> 0.57365182 | G7: ='Sale Summary'!E20 -> 3764366 | H7: =G7/(C7/30) -> 20.846788 | J7: ='Sale Summary'!F20 -> 4484438 | K7: =J7/(C7/30) -> 24.834495
B8: UHT-Chill | C8: ='Sale Summary'!C21 -> 43052.04 | D8: ='Sale Summary'!D21 -> 20928 | E8: =D8/C8 -> 0.48610937 | G8: ='Sale Summary'!E21 -> 27480 | H8: =G8/(C8/30) -> 19.148918 | J8: ='Sale Summary'!F21 -> 28294 | K8: =J8/(C8/30) -> 19.716139
A9: =C1-365 -> 45801 | B9: Grand Total | C9: =SUM(C3:C8) -> 6240121.9 | D9: =SUM(D3:D8) -> 3542684 | E9: =D9/C9 -> 0.56772673 | G9: =SUM(G3:G8) -> 4428393 | H9: =G9/(C9/30) -> 21.289935 | J9: =SUM(J3:J8) -> 5196505 | K9: =J9/(C9/30) -> 24.982709
A11: =TODAY() -> 46167 | B11: =TEXT(C1,"dd-mmm-yy")&" "&"sale" -> 24-May-26 sale | D11: ='Sale Summary'!J10 -> 176779 | E11: =D11/1000 -> 176.779
B12: Asking rate
B13: =TEXT(A9,"dd-mmm-yy")&" "&"LY Closing sale" -> 24-May-25 LY Closing sale | H13: CY Vs LY Diff.
B14: Variance CY Vs LY | D14: 63280 | H14: =(D9-D14)/1000 -> 3479.404 | L14: =D9/D14 -> 55.98426

Sheet Item wise
A1: Cat | B1: (All)
C3: Values
A4: Material Code | B4: Material Description | C4: Sum of RF May- 26 | D4: Sum of Sales Qty | E4: Sum of Ready + transist | F4: INV Days (R+T) | G4: Sale % To RF | H4: RF Pendency Overall (Not Hubwise)
A5: 00189 | B5: Rich's Star Whip 1 Kg | C5: 1088745.6 | D5: 631428 | E5: 489132 | F5: =E5/(C5/30) -> 13.477859 | G5: =D5/C5 -> 0.57995918 | H5: =C5-D5-E5 -> -31814.4
A6: 01167 | B6: Rich's Sweetmate (India) 1 Kg | C6: 129866.16 | D6: 84420 | E6: 90168 | F6: =E6/(C6/30) -> 20.829445 | G6: =D6/C6 -> 0.65005387 | H6: =C6-D6-E6 -> -44721.84
A7: 01296 | B7: Rich’s Cremagic - 2 Kg | C7: 67239.24 | D7: 35424 | E7: 52440 | F7: =E7/(C7/30) -> 23.397052 | G7: =D7/C7 -> 0.52683522 | H7: =C7-D7-E7 -> -20624.76
A8: 02122 | B8: Rich's Dairy Free Whip Topping - 2 Kg | C8: 306618.96 | D8: 176112 | E8: 335568 | F8: =E8/(C8/30) -> 32.832412 | G8: =D8/C8 -> 0.57436761 | H8: =C8-D8-E8 -> -205061.04
A9: 04145 | B9: Rich's Nugel Caramel (1 Kg) | C9: 3122.19 | D9: 2016 | E9: 5265 | F9: =E9/(C9/30) -> 50.58949 | G9: =D9/C9 -> 0.64570061 | H9: =C9-D9-E9 -> -4158.81
A10: 05159 | B10: Rich's Whip Topping-Gold 500 G (India) | C10: 15687.72 | D10: 8040 | E10: 29028 | F10: =E10/(C10/30) -> 55.510935 | G10: =D10/C10 -> 0.51250277 | H10: =C10-D10-E10 -> -21380.28
A11: 06151 | B11: Rich's Double Dream | C11: 317299.56 | D11: 160128 | E11: 188004 | F11: =E11/(C11/30) -> 17.775379 | G11: =D11/C11 -> 0.50465875 | H11: =C11-D11-E11 -> -30832.44
A12: 06982 | B12: Rich's Chocolate Whip Topping | C12: 100813.44 | D12: 59328 | E12: 89208 | F12: =E12/(C12/30) -> 26.54646 | G12: =D12/C12 -> 0.58849296 | H12: =C12-D12-E12 -> -47722.56
A13: 07310 | B13: Rich's Cooking Rich Hot Kitchen Appl. | C13: 707016.72 | D13: 376728 | E13: 661020 | F13: =E13/(C13/30) -> 28.048276 | G13: =D13/C13 -> 0.53284171 | H13: =C13-D13-E13 -> -330731.28
A14: 08529 | B14: Rich's Truffle Base | C14: 203547.36 | D14: 111756 | E14: 194472 | F14: =E14/(C14/30) -> 28.66242 | G14: =D14/C14 -> 0.54904176 | H14: =C14-D14-E14 -> -102680.64
A15: 13179 | B15: Rich’s Whip Topping Gold (India) | C15: 857921.04 | D15: 540564 | E15: 671700 | F15: =E15/(C15/30) -> 23.488176 | G15: =D15/C15 -> 0.63008596 | H15: =C15-D15-E15 -> -354342.96
A16: 13490 | B16: Rich's Nugel Neutral Glaze 2.5 Kg IN | C16: 51974.7 | D16: 32680 | E16: 68680 | F16: =E16/(C16/30) -> 39.642364 | G16: =D16/C16 -> 0.62876746 | H16: =C16-D16-E16 -> -49385.3
... A57: 23691 | B57: RICH'S WT Gold 1 Kg (Middle East) | C57: 0 | D57: 0 | E57: 240 | F57: =E57/(C57/30) -> #DIV/0! | G57: =D57/C57 -> #DIV/0! | H57: =C57-D57-E57 -> -240
A58: Grand Total | C58: 6240121.9 | D58: 3542684 | E58: 5197669 | F58: =E58/(C58/30) -> 24.988305 | G58: =D58/C58 -> 0.56772673 | H58: =C58-D58-E58 -> -2500231.1

Sheet ITEM_WISE
A1: Material Code | B1: Material Description | C1: Sum of RF May- 26 | D1: Sum of Sales Qty | E1: Sum of Ready + transist | F1: INV Days (R+T) | G1: Sale % to RF | H1: RF Pendency | I1: RF Pendency %
A2: 00189 | B2: Rich's Star Whip 1 Kg | C2: =VLOOKUP(A2,'Item wise'!A:H,3,) -> 1088745.6 | D2: =VLOOKUP(A2,'Item wise'!A:H,4,) -> 631428 | E2: =VLOOKUP(A2,'Item wise'!A:H,5,) -> 489132 | F2: =E2/(C2/30) -> 13.477859 | G2: =D2/C2 -> 0.57995918 | H2: =C2-D2-E2 -> -31814.4 | I2: =H2/C2 -> -0.029221151
A3: 13179 | B3: Rich’s Whip Topping Gold (India) | C3: =VLOOKUP(A3,'Item wise'!A:H,3,) -> 857921.04 | D3: =VLOOKUP(A3,'Item wise'!A:H,4,) -> 540564 | E3: =VLOOKUP(A3,'Item wise'!A:H,5,) -> 671700 | F3: =E3/(C3/30) -> 23.488176 | G3: =D3/C3 -> 0.63008596 | H3: =C3-D3-E3 -> -354342.96 | I3: =H3/C3 -> -0.41302514
A4: 16336 | B4: Sunwhip (India) 1 Kg | C4: =VLOOKUP(A4,'Item wise'!A:H,3,) -> 834183.48 | D4: =VLOOKUP(A4,'Item wise'!A:H,4,) -> 524808 | E4: =VLOOKUP(A4,'Item wise'!A:H,5,) -> 610680 | F4: =E4/(C4/30) -> 21.962075 | G4: =D4/C4 -> 0.62912778 | H4: =C4-D4-E4 -> -301304.52 | I4: =H4/C4 -> -0.36119694
A5: 07310 | B5: Rich's Cooking Rich Hot Kitchen Appl. | C5: =VLOOKUP(A5,'Item wise'!A:H,3,) -> 707016.72 | D5: =VLOOKUP(A5,'Item wise'!A:H,4,) -> 376728 | E5: =VLOOKUP(A5,'Item wise'!A:H,5,) -> 661020 | F5: =E5/(C5/30) -> 28.048276 | G5: =D5/C5 -> 0.53284171 | H5: =C5-D5-E5 -> -330731.28 | I5: =H5/C5 -> -0.46778424
A6: 06151 | B6: Rich's Double Dream | C6: =VLOOKUP(A6,'Item wise'!A:H,3,) -> 317299.56 | D6: =VLOOKUP(A6,'Item wise'!A:H,4,) -> 160128 | E6: =VLOOKUP(A6,'Item wise'!A:H,5,) -> 188004 | F6: =E6/(C6/30) -> 17.775379 | G6: =D6/C6 -> 0.50465875 | H6: =C6-D6-E6 -> -30832.44 | I6: =H6/C6 -> -0.097171392
A7: 02122 | B7: Rich's Dairy Free Whip Topping - 2 Kg | C7: =VLOOKUP(A7,'Item wise'!A:H,3,) -> 306618.96 | D7: =VLOOKUP(A7,'Item wise'!A:H,4,) -> 176112 | E7: =VLOOKUP(A7,'Item wise'!A:H,5,) -> 335568 | F7: =E7/(C7/30) -> 32.832412 | G7: =D7/C7 -> 0.57436761 | H7: =C7-D7-E7 -> -205061.04 | I7: =H7/C7 -> -0.66878134
A8: 14788 | B8: Rich’s Whip Topping-Gold 1 Kg | C8: =VLOOKUP(A8,'Item wise'!A:H,3,) -> 285586.44 | D8: =VLOOKUP(A8,'Item wise'!A:H,4,) -> 147672 | E8: =VLOOKUP(A8,'Item wise'!A:H,5,) -> 218856 | F8: =E8/(C8/30) -> 22.990167 | G8: =D8/C8 -> 0.51708337 | H8: =C8-D8-E8 -> -80941.56 | I8: =H8/C8 -> -0.28342228
A9: 08529 | B9: Rich's Truffle Base | C9: =VLOOKUP(A9,'Item wise'!A:H,3,) -> 203547.36 | D9: =VLOOKUP(A9,'Item wise'!A:H,4,) -> 111756 | E9: =VLOOKUP(A9,'Item wise'!A:H,5,) -> 194472 | F9: =E9/(C9/30) -> 28.66242 | G9: =D9/C9 -> 0.54904176 | H9: =C9-D9-E9 -> -102680.64 | I9: =H9/C9 -> -0.50445577
A10: 15536 | B10: Rich's Premium Truffle -2 Kg | C10: =VLOOKUP(A10,'Item wise'!A:H,3,) -> 187506.72 | D10: =VLOOKUP(A10,'Item wise'!A:H,4,) -> 96276 | E10: =VLOOKUP(A10,'Item wise'!A:H,5,) -> 231348 | F10: =E10/(C10/30) -> 37.014353 | G10: =D10/C10 -> 0.5134536 | H10: =C10-D10-E10 -> -140117.28 | I10: =H10/C10 -> -0.74726538
A11: 20308 | B11: Rich's Star Whip 2 kg | C11: =VLOOKUP(A11,'Item wise'!A:H,3,) -> 132859.56 | D11: =VLOOKUP(A11,'Item wise'!A:H,4,) -> 70704 | E11: =VLOOKUP(A11,'Item wise'!A:H,5,) -> 148104 | F11: =E11/(C11/30) -> 33.44223 | G11: =D11/C11 -> 0.53217096 | H11: =C11-D11-E11 -> -85948.44 | I11: =H11/C11 -> -0.64691197
A12: 01167 | B12: Rich's Sweetmate (India) 1 Kg | C12: =VLOOKUP(A12,'Item wise'!A:H,3,) -> 129866.16 | D12: =VLOOKUP(A12,'Item wise'!A:H,4,) -> 84420 | E12: =VLOOKUP(A12,'Item wise'!A:H,5,) -> 90168 | F12: =E12/(C12/30) -> 20.829445 | G12: =D12/C12 -> 0.65005387 | H12: =C12-D12-E12 -> -44721.84 | I12: =H12/C12 -> -0.34436869
A13: 23638 | B13: Rich's Versatie Gold- Cooking Base 1 ltr | C13: =VLOOKUP(A13,'Item wise'!A:H,3,) -> 106652.04 | D13: =VLOOKUP(A13,'Item wise'!A:H,4,) -> 48468 | E13: =VLOOKUP(A13,'Item wise'!A:H,5,) -> 70128 | F13: =E13/(C13/30) -> 19.726205 | G13: =D13/C13 -> 0.45444982 | H13: =C13-D13-E13 -> -11943.96 | I13: =H13/C13 -> -0.11198998
... A52: 24216 | B52: Versatie Export | C52: =VLOOKUP(A52,'Item wise'!A:H,3,) -> 0 | D52: =VLOOKUP(A52,'Item wise'!A:H,4,) -> 0 | E52: =VLOOKUP(A52,'Item wise'!A:H,5,) -> 216 | F52: =E52/(C52/30) -> #DIV/0! | G52: =D52/C52 -> #DIV/0! | H52: =C52-D52-E52 -> -216 | I52: =H52/C52 -> #DIV/0!
A53: Grand Total | C53: =SUM(C2:C52) -> 6240121.9 | D53: =SUM(D2:D52) -> 3542684 | E53: =SUM(E2:E52) -> 5196265 | G53: =D53/C53 -> 0.56772673

Sheet RF Pendency Pivot
D1: 4 | E1: 5 | F1: 6 | G1: 7 | H1: 8 | I1: 9 | J1: 10 | K1: 11 | L1: 12 | M1: 13 | N1: 14 | O1: 15 | P1: 16 | Q1: 17 | R1: 18 | S1: 19 | T1: 20 | U1: 21
D2: RPSPL-BNG | E2: RPSPL-CH | F2: RPSPL-DEL | G2: RPSPL-GT | H2: RPSPL-GUJ | I2: RPSPL-HP Factory | J2: RPSPL-HY | K2: RPSPL-KER | L2: RPSPL-KOL | M2: RPSPL-MP | N2: RPSPL-PBN | O2: RPSPL-PC | P2: RPSPL-RJ | Q2: RPSPL-NG | R2: RPSPL-PA | S2: RPSPL-KNP | T2: RPSPL-KH | U2: RPSPL-Sonipat
A3: Sum of RF Pendency | D3: Plant Name
A4: Material Code | B4: Material Description | C4: Cat | D4: RPSPL-BNG | E4: RPSPL-CH | F4: RPSPL-DEL | G4: RPSPL-GT | H4: RPSPL-GUJ | I4: RPSPL-HP Factory | J4: RPSPL-HY | K4: RPSPL-KER | L4: RPSPL-KOL | M4: RPSPL-MP | N4: RPSPL-PBN | O4: RPSPL-PC | P4: RPSPL-RJ | Q4: RPSPL-NG | R4: RPSPL-PA | S4: RPSPL-KNP | T4: RPSPL-KH | U4: RPSPL-Sonipat | V4: Grand Total
A5: 00189 | B5: Rich's Star Whip 1 Kg | C5: T&I | D5: 13663.2 | E5: -15716.04 | G5: -14290.92 | H5: 2520.48 | I5: 5266.08 | J5: 11456.04 | K5: 14091.96 | L5: 0 | M5: -17594.64 | N5: -893.4 | O5: -8828.76 | P5: -6212.04 | Q5: -3748.8 | R5: -70.56 | S5: -10200.96 | T5: 0 | U5: -1256.04 | V5: -31814.4
A6: 01167 | B6: Rich's Sweetmate (India) 1 Kg | C6: T&I | D6: -3527.16 | E6: -59.16 | G6: -1478.04 | H6: -4774.44 | J6: -6913.56 | K6: -2064 | L6: -1255.56 | M6: -1552.8 | N6: -6022.08 | O6: -7806.12 | P6: -1044 | Q6: -4351.2 | R6: -789.36 | S6: -1468.32 | U6: -1616.04 | V6: -44721.84
A7: 01296 | B7: Rich’s Cremagic - 2 Kg | C7: T&I | D7: -1051.32 | E7: -704.52 | G7: -253.32 | H7: -392.64 | I7: 550.2 | J7: -918.12 | K7: -2876.04 | L7: -3005.76 | M7: -1317.12 | N7: -711.36 | O7: -4966.8 | P7: -840 | Q7: -1965 | R7: -5.04 | S7: -1351.92 | U7: -816 | V7: -20624.76
A8: 02122 | B8: Rich's Dairy Free Whip Topping - 2 Kg | C8: T&I | D8: -32178.96 | E8: -5392.8 | G8: -1263.96 | H8: -8620.68 | I8: 54.36 | J8: -2409.96 | K8: -4368 | L8: -1063.8 | M8: -2501.16 | N8: -110868 | O8: -16238.28 | P8: -3132 | Q8: -2682.12 | R8: -210.72 | S8: -3088.92 | U8: -11096.04 | V8: -205061.04
A9: 05159 | B9: Rich's Whip Topping-Gold 500 G (India) | C9: T&I | D9: 82.56 | E9: -65.76 | G9: 1125.12 | H9: -467.28 | I9: -3624 | J9: -28.56 | K9: -2784 | L9: -480 | N9: -15036 | O9: -76.92 | P9: -24 | Q9: -1.44 | V9: -21380.28
A10: 06982 | B10: Rich's Chocolate Whip Topping | C10: T&I | D10: -1794.6 | E10: -52.56 | G10: -433.68 | H10: -6892.68 | J10: -3683.28 | K10: -7804.08 | L10: -96.24 | M10: -5761.2 | N10: -1644 | O10: -5334.24 | P10: -984 | Q10: -7108.68 | R10: -504 | S10: -4181.28 | U10: -1448.04 | V10: -47722.56
A11: 07310 | B11: Rich's Cooking Rich Hot Kitchen Appl. | C11: T&I | D11: -32952 | E11: -15032.64 | G11: -2489.64 | H11: -17929.56 | I11: 5526.96 | J11: -21795 | K11: -19074.24 | L11: -15092.4 | M11: -30022.8 | N11: -73307.16 | O11: -26913 | P11: -19792.08 | Q11: -14590.68 | R11: -2316.24 | S11: -11014.8 | U11: -33936 | V11: -330731.28
A12: 08529 | B12: Rich's Truffle Base | C12: T&I | D12: -15342.12 | E12: -7022.76 | G12: -2338.32 | H12: -5992.44 | I12: -2172 | J12: -5372.76 | K12: -648 | L12: -5307.48 | M12: -5410.32 | N12: -13201.44 | O12: -17130.72 | P12: -2964 | Q12: -6760.44 | R12: -5076 | S12: -3725.76 | U12: -4216.08 | V12: -102680.64
A13: 13179 | B13: Rich’s Whip Topping Gold (India) | C13: T&I | D13: -39369.36 | E13: -10682.88 | H13: -13057.8 | I13: -16514.28 | J13: -2426.64 | K13: -102488.04 | L13: -60 | M13: -7869.72 | N13: -87224.04 | O13: -34595.52 | P13: -4560 | Q13: -9004.44 | S13: -21334.2 | U13: -5156.04 | V13: -354342.96
A14: 13678 | B14: Rich’s New Niagara Farms | C14: T&I | D14: -1569.24 | E14: -1492.92 | G14: -32.04 | H14: -2771.88 | I14: -48 | J14: -4395.24 | K14: -836.76 | L14: -1207.56 | M14: -2633.64 | N14: -6052.08 | O14: -3025.44 | P14: -3016.08 | Q14: -5066.64 | R14: -122.04 | S14: -4476 | U14: -1232.04 | V14: -37977.6
A15: 14654 | B15: Rich's Bettercreme | C15: T&I | D15: -635.88 | E15: 118.68 | G15: -907.92 | H15: -0.12 | I15: -36 | J15: -58.32 | K15: -2904.24 | L15: -1011.12 | M15: -861.48 | N15: -12846.48 | O15: -2589.96 | P15: -12 | Q15: -417.48 | R15: -18.72 | S15: 947.76 | U15: 583.92 | V15: -20649.36
A16: 15459 | B16: Rich's Cooking Rich-Hot Kitchen (10 Kg) | C16: T&I | I16: -220 | K16: -13254.8 | N16: -39920 | O16: -6180 | V16: -59574.8
A17: 16336 | B17: Sunwhip (India) 1 Kg | C17: T&I | D17: -36207.72 | E17: -5017.32 | G17: -6255.12 | H17: -16716.12 | I17: 1567.8 | J17: -33542.76 | K17: -20900.04 | L17: -27810.72 | M17: -40515.48 | N17: 447.12 | O17: -37991.64 | P17: -15248.04 | Q17: -33036.12 | R17: -8062.8 | S17: -18895.56 | U17: -3120 | V17: -301304.52
A18: 16984 | B18: Rich’s Niagara Farms Gold (1 Kg ) | C18: T&I | D18: -561.12 | E18: -616.56 | G18: -702.72 | H18: -308.88 | I18: -180 | J18: -380.52 | K18: -526.56 | L18: -17.64 | M18: -6860.88 | N18: -396 | O18: -2768.88 | P18: -204 | Q18: -187.68 | R18: -3.36 | S18: -234.72 | U18: -1108.08 | V18: -15057.6
A19: 16998 | B19: Rich's Excel Whip (1 Kg) | C19: T&I | D19: -1211.52 | E19: -3.12 | G19: -1121.64 | H19: -5127.96 | J19: -83.28 | K19: -1219.2 | L19: -1296.24 | M19: -31861.68 | N19: -8712 | O19: -4912.8 | P19: -5424 | Q19: -5763.96 | R19: -958.44 | S19: -2513.64 | U19: -3932.04 | V19: -74141.52
A20: 18098 | B20: Rich's ICEHOT All in one beverage base | C20: T&I | D20: -3245.4 | E20: -120 | G20: -219.36 | H20: -93.36 | J20: 1.44 | K20: -255.6 | L20: -86.04 | M20: -203.04 | N20: -2864.04 | O20: -3700.92 | P20: -368.04 | Q20: -381 | R20: -835.08 | S20: -328.32 | U20: -40.08 | V20: -12738.84
A21: 14788 | B21: Rich’s Whip Topping-Gold 1 Kg | C21: T&I | D21: -4152.48 | E21: -1410.48 | G21: -9168 | H21: 891.6 | J21: -719.52 | K21: -27092.04 | L21: -1681.68 | M21: -4450.08 | N21: -4129.56 | O21: -20747.16 | P21: 4515.96 | Q21: -6007.32 | R21: -6466.8 | U21: -324 | V21: -80941.56
A22: 15906 | B22: Rich’s Whip Topping (India) 1 Kg | C22: T&I | D22: -15547.2 | E22: -410.28 | H22: -1693.2 | I22: -36 | J22: -114.72 | K22: -58.68 | L22: -799.08 | M22: -480 | N22: -12396 | O22: -2119.92 | P22: -720 | Q22: -3012.12 | S22: -252 | U22: -1296 | V22: -38935.2
A23: 20308 | B23: Rich's Star Whip 2 kg | C23: T&I | D23: -8836.68 | E23: -2930.16 | G23: -2880 | H23: -8613.84 | I23: -144 | J23: -5665.8 | K23: -10931.76 | L23: -104.16 | M23: -3733.44 | N23: -21936 | O23: -15683.04 | R23: -1315.56 | S23: -2133.96 | U23: -1040.04 | V23: -85948.44
A24: 21910 | B24: Rich’s Sunwhip 2 Kg | C24: T&I | D24: -3.24 | E24: -783.96 | H24: -1606.56 | I24: -108 | J24: -59.4 | K24: -579.24 | L24: -5397.36 | N24: -51420 | O24: -1690.68 | R24: -2553.48 | S24: -2285.76 | U24: -3512.04 | V24: -69999.72
A25: 23081 | B25: Rich’s Icehot Creamery Dairy Beverage MI | C25: T&I | D25: -18.84 | E25: -192.24 | G25: -3.36 | H25: -42.72 | I25: -144 | J25: -299.76 | K25: 368.76 | L25: 108.6 | M25: -106.32 | N25: 24 | O25: -713.64 | P25: -84 | Q25: -114.72 | R25: -568.68 | S25: 162.36 | U25: 223.92 | V25: -1400.64
A26: 23401 | B26: New Toppin Pride (1 kg) | C26: T&I | D26: -1370.04 | E26: -18.6 | G26: -3153.96 | H26: 4.08 | J26: 3074.52 | K26: -4736.04 | L26: -364.92 | M26: -33036 | N26: 2106 | O26: -96 | Q26: -2359.92 | R26: -178.44 | S26: 424.92 | U26: -192 | V26: -39896.4
A27: 06151 | B27: Rich's Double Dream | C27: DD | D27: 700.56 | E27: -10335.36 | G27: 256.44 | H27: 2769.48 | J27: 6219 | K27: -4.08 | L27: -5765.16 | M27: -6857.76 | N27: 3063.96 | O27: 419.28 | P27: -4580.04 | Q27: -7164.36 | R27: -9132 | S27: 9097.68 | U27: -9520.08 | V27: -30832.44
A28: 20661 | B28: Rich’s Wilber Farms Dairy Cream 1ltr | C28: UHT-Chill | D28: -2304.6 | E28: -1239.84 | G28: 154.32 | H28: 448.32 | J28: -2629.44 | K28: 4299.96 | L28: -67.44 | M28: 1202.64 | N28: 1423.92 | O28: -3261.96 | P28: 282 | Q28: -407.64 | R28: -1000.92 | S28: 153.96 | U28: 243.92 | V28: -2702.8
A29: 04145 | B29: Rich's Nugel Caramel (1 Kg) | C29: NGL | D29: -294.21 | E29: -12.42 | G29: -86.04 | H29: -22.32 | J29: -101.07 | K29: -162.63 | L29: -774 | M29: -1191.42 | N29: -189 | O29: -5.58 | P29: -45 | Q29: -200.52 | R29: -329.58 | S29: -358.02 | U29: -387 | V29: -4158.81
A30: 13490 | B30: Rich's Nugel Neutral Glaze 2.5 Kg IN | C30: NGL | D30: -4794.6 | E30: -65.2 | G30: 78.1 | H30: -6118.4 | J30: -6094 | K30: -1891.5 | L30: -1202.2 | M30: -16635.1 | N30: -3950 | O30: 244.9 | P30: -900 | Q30: -1567.3 | R30: -1990 | S30: -2040 | U30: -2460 | V30: -49385.3
A31: 14248 | B31: Rich's Nugel Cocoa Glaze 2.5 Kg (India) | C31: NGL | D31: -1253.8 | E31: 2.8 | G31: -311.8 | H31: -175.4 | J31: -891.1 | K31: -88 | L31: -610.7 | M31: -13020.4 | N31: -240 | O31: 1200.8 | P31: 80 | Q31: -203.2 | R31: -288.6 | S31: -1030 | U31: -1510 | V31: -18339.4
A32: 15300 | B32: Rich's Nugel Pineapple Glaze 1.0 Kg IN | C32: NGL | D32: -237.42 | E32: -4.23 | G32: 0 | H32: -4.41 | J32: -53.55 | K32: -13.14 | L32: 131.31 | M32: -1268.19 | N32: -27 | O32: 3.15 | P32: -63 | Q32: -242.19 | R32: -236.97 | S32: -390.06 | U32: -234 | V32: -2639.7
A33: 15305 | B33: Rich's Nugel Strawberry Glaze 1.0 Kg IN | C33: NGL | D33: -101.97 | E33: 19.35 | G33: -59.58 | H33: -6.93 | L33: -86.04 | M33: -3428.64 | N33: -225 | O33: -72.18 | P33: -81 | Q33: -61.83 | R33: -182.97 | S33: -3.06 | U33: -279 | V33: -4568.85
A34: 15312 | B34: Rich's Nugel Blueberry Glaze 1.0 Kg IN | C34: NGL | D34: -79.11 | E34: -13.23 | G34: -76.77 | L34: -116.55 | M34: -1602 | N34: -369 | O34: -1.44 | Q34: -28.26 | R34: -2.97 | S34: -92.07 | V34: -2381.4
A35: 16407 | B35: Rich's Nugel White 1 Kg (India) | C35: NGL | D35: -520.38 | E35: -5.49 | G35: -140.58 | H35: -557.55 | J35: -210.6 | K35: -255.33 | L35: -96.03 | M35: -1930.41 | N35: -441 | O35: -83.52 | P35: -144 | Q35: -177.93 | R35: -0.09 | S35: -4.68 | U35: -423 | V35: -4990.59
A36: 15536 | B36: Rich's Premium Truffle -2 Kg | C36: Ganache | D36: -11385.6 | E36: -3961.92 | G36: -521.64 | H36: -3466.92 | J36: -4641.72 | K36: -1224 | L36: -3439.8 | M36: -49303.32 | N36: -8249.4 | O36: -12191.88 | P36: -10436.04 | Q36: -4580.64 | R36: -5514.6 | S36: -8407.8 | U36: -12792 | V36: -140117.28
A37: 20827 | B37: Rich’s Premium Truffle-RTUGanache-GS 2kg | C37: Ganache | D37: -866.88 | E37: -327.72 | G37: -277.68 | H37: -5021.16 | J37: -1148.04 | K37: -2568 | L37: -1209.36 | M37: -5538.24 | N37: -7972.08 | O37: -2461.32 | P37: -4840.08 | Q37: -3078.24 | R37: -861.36 | S37: -1620.6 | U37: -8564.04 | V37: -46354.8
A38: 23638 | B38: Rich's Versatie Gold- Cooking Base 1 ltr | C38: DD | D38: -10973.52 | E38: -915 | G38: -1139.64 | H38: -2796 | J38: -8180.28 | K38: 3712.68 | L38: 2767.08 | M38: -11812.08 | N38: 5587.92 | O38: 7327.92 | P38: 1176 | Q38: 3175.92 | R38: -1540.32 | S38: 2165.52 | U38: -500.16 | V38: -11943.96
A39: 24768 | B39: RWT Silver India 1kg | C39: T&I | D39: -25210.68 | E39: -1139.64 | G39: -19.56 | H39: -2649.36 | J39: -3030 | K39: -1332 | L39: -1202.52 | M39: -3445.2 | N39: -1147.08 | O39: -3637.68 | P39: -2488.08 | Q39: -4147.8 | R39: -2428.44 | S39: -3417.96 | U39: -6036.12 | V39: -61332.12
A40: 25616 | B40: RWT Gold - 10 kg | C40: T&I | E40: -3520.3 | N40: -16180 | V40: -19700.3
...

Sheet INV Days Pivot
D1: 4 | E1: 5 | F1: 6 | G1: 7 | H1: 8 | I1: 9 | J1: 10 | K1: 11 | L1: 12 | M1: 13 | N1: 14 | O1: 15 | P1: 16 | Q1: 17 | R1: 18 | S1: 19 | T1: 20 | U1: 21
D2: RPSPL-BNG | E2: RPSPL-CH | F2: RPSPL-DEL | G2: RPSPL-GT | H2: RPSPL-GUJ | I2: RPSPL-HP Factory | J2: RPSPL-HY | K2: RPSPL-KER | L2: RPSPL-KOL | M2: RPSPL-MP | N2: RPSPL-PBN | O2: RPSPL-PC | P2: RPSPL-RJ | Q2: RPSPL-NG | R2: RPSPL-PA | S2: RPSPL-KNP | T2: RPSPL-KH | U2: RPSPL-Sonipat
A3: Average of INV Days R+T | D3: Plant Name
A4: Material Code | B4: Material Description | C4: Cat | D4: RPSPL-BNG | E4: RPSPL-CH | F4: RPSPL-DEL | G4: RPSPL-GT | H4: RPSPL-GUJ | I4: RPSPL-HP Factory | J4: RPSPL-HY | K4: RPSPL-KER | L4: RPSPL-KOL | M4: RPSPL-MP | N4: RPSPL-PBN | O4: RPSPL-PC | P4: RPSPL-RJ | Q4: RPSPL-NG | R4: RPSPL-PA | S4: RPSPL-KNP | T4: RPSPL-KH | U4: RPSPL-Sonipat | V4: Grand Total
A5: 00189 | B5: Rich's Star Whip 1 Kg | C5: T&I | D5: 10.290835 | E5: 25.093916 | G5: 29.53974 | H5: 16.785468 | I5: 5.6127742 | J5: 8.6427633 | K5: 4.2750043 | L5: 9.57 | M5: 4.4662588 | N5: 15.850346 | O5: 14.78306 | P5: 30.960108 | Q5: 13.025949 | R5: 15.089687 | S5: 20.714059 | T5: 0 | U5: 10.260012 | V5: 13.821175
A6: 01167 | B6: Rich's Sweetmate (India) 1 Kg | C6: T&I | D6: 18.054197 | E6: 21.144295 | G6: 51.109868 | H6: 53.728681 | J6: 15.786437 | K6: 18.63 | L6: 27.013347 | M6: 38.112927 | N6: 20.994002 | O6: 17.814162 | P6: 36.25 | Q6: 25.962708 | R6: 34.135422 | S6: 27.179706 | U6: 22.430298 | V6: 28.556403
A7: 01296 | B7: Rich’s Cremagic - 2 Kg | C7: T&I | D7: 24.089707 | E7: 30.230794 | G7: 35.672651 | H7: 18.95012 | I7: 0 | J7: 24.219943 | K7: 26.574739 | L7: 28.064396 | M7: 40.763968 | N7: 19.100951 | O7: 20.135987 | P7: 22.086614 | Q7: 27.279503 | R7: 25.315331 | S7: 26.974393 | U7: 22.241379 | V7: 24.48128
A8: 02122 | B8: Rich's Dairy Free Whip Topping - 2 Kg | C8: T&I | D8: 26.078654 | E8: 32.885141 | G8: 48.976548 | H8: 35.994703 | I8: 28.54699 | J8: 21.482617 | K8: 31.918605 | L8: 16.373469 | M8: 36.100974 | N8: 223.152 | O8: 20.820449 | P8: 32.76 | Q8: 39.445879 | R8: 47.574627 | S8: 19.084523 | U8: 17.247281 | V8: 42.402654
A9: 05159 | B9: Rich's Whip Topping-Gold 500 G (India) | C9: T&I | D9: 15.625 | E9: 29.275093 | G9: 11.374938 | H9: 28.467595 | I9: 0 | J9: 49.723757 | K9: 20.44 | L9: 0 | N9: 0 | O9: 26.590693 | P9: 0 | Q9: 31.25 | V9: 17.728923
A10: 06982 | B10: Rich's Chocolate Whip Topping | C10: T&I | D10: 16.938905 | E10: 16.813513 | G10: 40.592372 | H10: 41.29141 | J10: 40.592101 | K10: 19.513533 | L10: 17.972866 | M10: 91.492777 | N10: 17.653846 | O10: 18.532898 | P10: 75.319149 | Q10: 38.001097 | R10: 0 | S10: 56.719073 | U10: 24.42892 | V10: 34.390831
A11: 07310 | B11: Rich's Cooking Rich Hot Kitchen Appl. | C11: T&I | D11: 25.819706 | E11: 40.672002 | G11: 49.503566 | H11: 24.098389 | I11: 5.1744583 | J11: 37.610928 | K11: 46.177053 | L11: 31.481217 | M11: 44.020332 | N11: 45.236675 | O11: 18.872088 | P11: 39.024156 | Q11: 47.712923 | R11: 34.966665 | S11: 27.066075 | U11: 18.410769 | V11: 33.490438
A12: 08529 | B12: Rich's Truffle Base | C12: T&I | D12: 33.852343 | E12: 33.896461 | G12: 42.85075 | H12: 34.590419 | I12: 0 | J12: 22.946048 | K12: 16.128 | L12: 34.927275 | M12: 37.17868 | N12: 35.050063 | O12: 22.328365 | P12: 34.86 | Q12: 38.119164 | R12: 30.665323 | S12: 25.640229 | U12: 20.295487 | V12: 28.958038
A13: 13179 | B13: Rich’s Whip Topping Gold (India) | C13: T&I | D13: 23.583288 | E13: 22.787697 | H13: 35.438884 | I13: 62.745378 | J13: 10.217507 | K13: 23.53255 | L13: 0 | M13: 26.971502 | N13: 39.511419 | O13: 22.709439 | P13: 24.96 | Q13: 30.4744 | S13: 24.081307 | U13: 12.002405 | V13: 25.643984
A14: 13678 | B14: Rich’s New Niagara Farms | C14: T&I | D14: 31.539889 | E14: 164.67463 | G14: 17.25478 | H14: 26.715539 | I14: 0 | J14: 21.933574 | K14: 29.15317 | L14: 27.173189 | M14: 32.032377 | N14: 25.489566 | O14: 24.838883 | P14: 26.100653 | Q14: 34.961451 | R14: 21.451222 | S14: 21.24 | U14: 22.535701 | V14: 32.943414
A15: 14654 | B15: Rich's Bettercreme | C15: T&I | D15: 11.224644 | E15: 7.5724606 | G15: 19.764647 | H15: 16.262779 | I15: 0 | J15: 11.84196 | K15: 36.540396 | L15: 27.892479 | M15: 25.461807 | N15: 39.04776 | O15: 20.303636 | P15: 17.88 | Q15: 23.750089 | R15: 27.420257 | S15: 5.9443331 | U15: 11.567289 | V15: 18.904659
A16: 15459 | B16: Rich's Cooking Rich-Hot Kitchen (10 Kg) | C16: T&I | I16: 0 | K16: 39.104166 | N16: 0 | O16: 32.750583 | V16: 17.963687
A17: 16336 | B17: Sunwhip (India) 1 Kg | C17: T&I | D17: 24.491938 | E17: 21.391306 | G17: 37.243253 | H17: 24.149009 | I17: 1.7309773 | J17: 61.110865 | K17: 29.635757 | L17: 27.921991 | M17: 96.965925 | N17: 8.6804141 | O17: 16.171572 | P17: 26.847027 | Q17: 29.67816 | R17: 13.714331 | S17: 19.362139 | U17: 12.310345 | V17: 28.212813
A18: 16984 | B18: Rich’s Niagara Farms Gold (1 Kg ) | C18: T&I | D18: 31.094527 | E18: 27.202696 | G18: 90.951493 | H18: 20.860573 | I18: 0 | J18: 95.659876 | K18: 189.32039 | L18: 13.564536 | M18: 118.03162 | N18: 70.588235 | O18: 36.653884 | P18: 42.5 | Q18: 106.34328 | R18: 16.791045 | S18: 51.772388 | U18: 38.816109 | V18: 59.384416
A19: 16998 | B19: Rich's Excel Whip (1 Kg) | C19: T&I | D19: 41.683327 | E19: 13.729977 | G19: 38.875682 | H19: 42.797775 | J19: 131.06796 | K19: 64.09396 | L19: 26.015199 | M19: 219.72133 | N19: 38.76 | O19: 22.469761 | P19: 38.366834 | Q19: 43.852213 | R19: 56.293208 | S19: 49.503566 | U19: 35.640356 | V19: 57.524743
A20: 18098 | B20: Rich's ICEHOT All in one beverage base | C20: T&I | D20: 36.953398 | E20: 0 | G20: 81.156716 | H20: 23.782876 | J20: 29.126214 | K20: 44.295302 | L20: 23.503078 | M20: 61.567164 | N20: 84.741069 | O20: 23.560372 | P20: 29.881195 | Q20: 39.792746 | R20: 52.232309 | S20: 28.618631 | U20: 29.304469 | V20: 39.234369
A21: 14788 | B21: Rich’s Whip Topping-Gold 1 Kg | C21: T&I | D21: 21.264968 | E21: 23.401815 | G21: 34.426667 | H21: 16.411422 | J21: 56.462358 | K21: 26.397837 | L21: 15.152968 | M21: 29.992662 | N21: 28.468991 | O21: 23.526917 | P21: 15.57821 | Q21: 20.797154 | R21: 25.747854 | U21: 50.25 | V21: 27.705702
A22: 15906 | B22: Rich’s Whip Topping (India) 1 Kg | C22: T&I | D22: 91.249297 | E22: 38.154392 | H22: 34.991974 | I22: 0 | J22: 44.031311 | K22: 58.708415 | L22: 36.189529 | M22: 0 | N22: 0 | O22: 21.576999 | P22: 32.386364 | Q22: 34.552153 | S22: 0 | U22: 24.64 | V22: 29.748602
A23: 20308 | B23: Rich's Star Whip 2 kg | C23: T&I | D23: 37.05699 | E23: 34.889481 | G23: 0 | H23: 27.391482 | I23: 0 | J23: 25.757995 | K23: 29.998795 | L23: 25.912997 | M23: 59.672572 | N23: 0 | O23: 22.320712 | R23: 38.761755 | S23: 33.493299 | U23: 24.750619 | V23: 25.714764
A24: 21910 | B24: Rich’s Sunwhip 2 Kg | C24: T&I | D24: 30.927835 | E24: 226.85789 | H24: 34.739152 | I24: 0 | J24: 78.688525 | K24: 37.780007 | L24: 67.711248 | N24: 0 | O24: 26.984377 | R24: 34.072472 | S24: 23.495773 | U24: 25.776103 | V24: 48.919448
A25: 23081 | B25: Rich’s Icehot Creamery Dairy Beverage MI | C25: T&I | D25: 25.444655 | E25: 45.050056 | G25: 30.783582 | H25: 18.190299 | I25: 0 | J25: 20.799742 | K25: 17.120797 | L25: 24.783478 | M25: 154.20561 | N25: 28.666667 | O25: 13.984058 | P25: 30 | Q25: 22.38806 | R25: 55.400112 | S25: 17.899594 | U25: 17.007366 | V25: 32.607754
A26: 23401 | B26: New Toppin Pride (1 kg) | C26: T&I | D26: 17.532649 | E26: 18.37043 | G26: 34.463038 | H26: 26.639148 | J26: 9.7638451 | K26: 17.354531 | L26: 21.7576 | M26: 0 | N26: 14.978602 | O26: 22.32 | Q26: 50.398387 | R26: 25.019203 | S26: 16.788957 | U26: 22.941176 | V26: 21.309112
A27: 06151 | B27: Rich's Double Dream | C27: DD | D27: 10.505184 | E27: 55.127944 | G27: 16.463756 | H27: 14.351818 | J27: 12.176894 | K27: 13.500135 | L27: 26.652842 | M27: 40.138613 | N27: 11.047528 | O27: 16.168058 | P27: 24.784692 | Q27: 34.057135 | R27: 47.264654 | S27: 0.14182832 | U27: 26.36483 | V27: 23.249727
A28: 20661 | B28: Rich’s Wilber Farms Dairy Cream 1ltr | C28: UHT-Chill | D28: 18.440871 | E28: 69.40874 | G28: 0 | H28: 0 | J28: 30.545113 | K28: 3.6000176 | L28: 20.526922 | M28: 0 | N28: 2.2987151 | O28: 30.584081 | P28: 7.0408163 | Q28: 17.011117 | R28: 76.962944 | S28: 27.047193 | U28: 6.0001371 | V28: 20.631111
A29: 04145 | B29: Rich's Nugel Caramel (1 Kg) | C29: NGL | D29: 29.720805 | E29: 41.436464 | G29: 22.38806 | H29: 47.619048 | J29: 52.924791 | K29: 47.844064 | L29: 49.875 | M29: 289.32969 | N29: 49.5 | O29: 4.3406366 | P29: 50 | Q29: 40.419162 | R29: 144.98141 | S29: 54.003724 | U29: 45 | V29: 64.625523
A30: 13490 | B30: Rich's Nugel Neutral Glaze 2.5 Kg IN | C30: NGL | D30: 25.613426 | E30: 15.64143 | G30: 25.171891 | H30: 157.24683 | J30: 29.942898 | K30: 23.58525 | L30: 26.865846 | M30: 656.2137 | N30: 41.175 | O30: 0 | P30: 50.333333 | Q30: 33.02829 | R30: 51.139896 | S30: 41.036269 | U30: 34.775087 | V30: 80.78461
A31: 14248 | B31: Rich's Nugel Cocoa Glaze 2.5 Kg (India) | C31: NGL | D31: 41.836568 | E31: 11.889036 | G31: 49.217002 | H31: 28.189255 | J31: 37.155537 | K31: 58.695652 | L31: 35.266686 | M31: 3025.463 | N31: 11.775701 | O31: 6.6882854 | P31: 0 | Q31: 13.372957 | R31: 21.380045 | S31: 36.062176 | U31: 36.734694 | V31: 227.58177
A32: 15300 | B32: Rich's Nugel Pineapple Glaze 1.0 Kg IN | C32: NGL | D32: 36.555646 | E32: 0 | G32: 0 | H32: 24.810476 | J32: 59.259259 | K32: 111.11111 | L32: 13.641133 | M32: 206.58294 | N32: 31.428571 | O32: 4.4609665 | P32: 38.823529 | Q32: 51.97055 | R32: 59.481444 | S32: 38.017145 | U32: 45.882353 | V32: 48.135008
A33: 15305 | B33: Rich's Nugel Strawberry Glaze 1.0 Kg IN | C33: NGL | D33: 41.522491 | E33: 0 | G33: 33.457249 | H33: 29.252438 | L33: 27.985075 | M33: 1902.3179 | N33: 330 | O33: 35.248042 | P33: 46.666667 | Q33: 40.590406 | R33: 50.330452 | S33: 19.008572 | U33: 42.857143 | V33: 199.94126
A34: 15312 | B34: Rich's Nugel Blueberry Glaze 1.0 Kg IN | C34: NGL | D34: 23.506366 | E34: 39.215686 | G34: 64.257028 | L34: 42.990654 | M34: 0 | N34: 307.5 | O34: 27.540564 | Q34: 64.516129 | R34: 22.877478 | S34: 50.139276 | V34: 64.254318
A35: 16407 | B35: Rich's Nugel White 1 Kg (India) | C35: NGL | D35: 44.174968 | E35: 25.341131 | G35: 94.795539 | H35: 51.391863 | J35: 36.090226 | K35: 64.55542 | L35: 25.182652 | M35: 467.26396 | N35: 34.615385 | O35: 17.749863 | P35: 45 | Q35: 21.82406 | R35: 19.539428 | S35: 18.886402 | U35: 32.790698 | V35: 66.613439
A36: 15536 | B36: Rich's Premium Truffle -2 Kg | C36: Ganache | D36: 23.544831 | E36: 30.429998 | G36: 22.094812 | H36: 33.326799 | J36: 21.573571 | K36: 32 | L36: 32.411264 | M36: 560.82399 | N36: 23.385897 | O36: 30.455773 | P36: 47.41219 | Q36: 44.843171 | R36: 31.262569 | S36: 39.199354 | U36: 29.505882 | V36: 66.818007
A37: 20827 | B37: Rich’s Premium Truffle-RTUGanache-GS 2kg | C37: Ganache | D37: 11.049724 | E37: 22.259058 | G37: 23.652248 | H37: 31.406129 | J37: 16.200295 | K37: 47.828571 | L37: 22.663682 | M37: 62.944678 | N37: 33.988635 | O37: 21.456189 | P37: 60.687101 | Q37: 40.293306 | R37: 33.855624 | S37: 24.716054 | U37: 29.700106 | V37: 32.180093
A38: 23638 | B38: Rich's Versatie Gold- Cooking Base 1 ltr | C38: DD | D38: 58.8283 | E38: 21.535807 | G38: 43.646945 | H38: 49.05 | J38: 45.132473 | K38: 0 | L38: 6.7759382 | M38: 78.553257 | N38: 8.3342922 | O38: 5.3100212 | P38: 7.26 | Q38: 0 | R38: 27.339586 | S38: 9.9055831 | U38: 15.777611 | V38: 25.163321
A39: 24768 | B39: RWT Silver India 1kg | C39: T&I | D39: 97.319958 | E39: 35.695087 | G39: 22.138157 | H39: 27.704124 | J39: 38.691589 | K39: 31.08 | L39: 26.591193 | M39: 50.24077 | N39: 17.514096 | O39: 33.812342 | P39: 21.703353 | Q39: 53.076512 | R39: 49.405745 | S39: 41.251212 | U39: 21.747826 | V39: 37.864798
A40: 25616 | B40: RWT Gold - 10 kg | C40: T&I | E40: 29.423327 | N40: 0 | V40: 14.711663
...

Sheet HUB wise lifting
B1: Cat | C1: DD | K1: Cat | L1: Ganache | T1: Cat | U1: NFL | AC1: Cat | AD1: NGL | AL1: Cat | AM1: T&I | AU1: Cat | AV1: UHT-Chill
C3: Values | L3: Values | U3: Values | AD3: Values | AM3: Values | AV3: Values
B4: Plant Name | C4: Sum of RF May- 26 | D4: Sum of Sales Qty | E4: Sum of Ready Stock | F4: Sum of Ready + transist | G4: Sale % | H4: INV Days | K4: Plant Name | L4: Sum of RF May- 26 | M4: Sum of Sales Qty | N4: Sum of Ready Stock | O4: Sum of Ready + transist | P4: Sale % | Q4: INV Days | T4: Plant Name | U4: Sum of RF May- 26 | V4: Sum of Sales Qty | W4: Sum of Ready Stock | X4: Sum of Ready + transist | Y4: Sale % | Z4: INV Days | AC4: Plant Name | AD4: Sum of RF May- 26 | AE4: Sum of Sales Qty | AF4: Sum of Ready Stock | AG4: Sum of Ready + transist | AH4: Sale % | AI4: INV Days | AL4: Plant Name | AM4: Sum of RF May- 26 | AN4: Sum of Sales Qty | AO4: Sum of Ready Stock | AP4: Sum of Ready + transist | AQ4: Sale % | AR4: INV Days | AU4: Plant Name | AV4: Sum of RF May- 26 | AW4: Sum of Sales Qty | AX4: Sum of Ready Stock | AY4: Sum of Ready + transist | AZ4: Sale % | BA4: INV Days
B5: RPSPL-BNG | C5: 59170.56 | D5: 37812 | E5: 20868 | F5: 31944 | G5: =D5/C5 -> 0.63903401 | H5: =E5/(C5/30) -> 10.580262 | K5: RPSPL-BNG | L5: 39731.52 | M5: 24384 | N5: 25200 | O5: 27600 | P5: =M5/L5 -> 0.61371928 | Q5: =N5/(L5/30) -> 19.027714 | T5: RPSPL-BNG | U5: 209.76 | V5: 252 | W5: 1404 | X5: 1404 | Y5: =V5/U5 -> 1.201373 | Z5: =W5/(U5/30) -> 200.80092 | AC5: RPSPL-BNG | AD5: 10508.51 | AE5: 7741 | AF5: 8444 | AG5: 10049 | AH5: =AE5/AD5 -> 0.73664107 | AI5: =AF5/(AD5/30) -> 24.106177 | AL5: RPSPL-BNG | AM5: 619326.6 | AN5: 371916 | AO5: 281424 | AP5: 461316 | AQ5: =AN5/AM5 -> 0.60051675 | AR5: =AO5/(AM5/30) -> 13.632097 | AU5: RPSPL-BNG | AV5: 8843.4 | AW5: 5712 | AX5: 5436 | AY5: 5436 | AZ5: =AW5/AV5 -> 0.64590542 | BA5: =AX5/(AV5/30) -> 18.440871
B6: RPSPL-CH | C6: 12893.64 | D6: 4344 | E6: 19800 | F6: 19800 | G6: =D6/C6 -> 0.33691029 | H6: =E6/(C6/30) -> 46.069225 | K6: RPSPL-CH | L6: 10026.36 | M6: 4560 | N6: 9756 | O6: 9756 | P6: =M6/L6 -> 0.45480114 | Q6: =N6/(L6/30) -> 29.191052 | T6: RPSPL-CH | U6: 122.64 | V6: 12 | W6: 216 | X6: 216 | Y6: =V6/U6 -> 0.097847358 | Z6: =W6/(U6/30) -> 52.837573 | AC6: RPSPL-CH | AD6: 5121.58 | AE6: 2520 | AF6: 2680 | AG6: 2680 | AH6: =AE6/AD6 -> 0.49203566 | AI6: =AF6/(AD6/30) -> 15.698281 | AL6: RPSPL-CH | AM6: 281850.86 | AN6: 104760 | AO6: 195348 | AP6: 249936 | AQ6: =AN6/AM6 -> 0.37168593 | AR6: =AO6/(AM6/30) -> 20.792699 | AU6: RPSPL-CH | AV6: 560.16 | AW6: 504 | AX6: 1296 | AY6: 1296 | AZ6: =AW6/AV6 -> 0.89974293 | BA6: =AX6/(AV6/30) -> 69.40874
B7: RPSPL-GT | C7: 6112.8 | D7: 2184 | E7: 4812 | F7: 4812 | G7: =D7/C7 -> 0.35728308 | H7: =E7/(C7/30) -> 23.616019 | K7: RPSPL-GT | L7: 3700.68 | M7: 1716 | N7: 2784 | O7: 2784 | P7: =M7/L7 -> 0.46369856 | Q7: =N7/(L7/30) -> 22.568825 | T7: RPSPL-DEL | U7: 0 | V7: 0 | W7: 0 | X7: 0 | Y7: =V7/U7 -> #DIV/0! | Z7: =W7/(U7/30) -> #DIV/0! | AC7: RPSPL-GT | AD7: 1573.33 | AE7: 515 | AF7: 1655 | AG7: 1655 | AH7: =AE7/AD7 -> 0.3273312 | AI7: =AF7/(AD7/30) -> 31.55727 | AL7: RPSPL-GT | AM7: 92991.96 | AN7: 38052 | AO7: 102876 | AP7: 102876 | AQ7: =AN7/AM7 -> 0.40919667 | AR7: =AO7/(AM7/30) -> 33.188676 | AU7: RPSPL-GT | AV7: 154.32 | AW7: 0 | AX7: 0 | AY7: 0 | AZ7: =AW7/AV7 -> 0 | BA7: =AX7/(AV7/30) -> 0
B8: RPSPL-GUJ | C8: 53647.56 | D8: 23676 | E8: 27012 | F8: 27012 | G8: =D8/C8 -> 0.44132482 | H8: =E8/(C8/30) -> 15.105254 | K8: RPSPL-GUJ | L8: 14323.92 | M8: 7464 | N8: 15348 | O8: 15348 | P8: =M8/L8 -> 0.52108641 | Q8: =N8/(L8/30) -> 32.144832 | T8: RPSPL-GT | U8: 321.6 | V8: 0 | W8: 168 | X8: 168 | Y8: =V8/U8 -> 0 | Z8: =W8/(U8/30) -> 15.671642 | AC8: RPSPL-GUJ | AD8: 3062.99 | AE8: 1023 | AF8: 8925 | AG8: 8925 | AH8: =AE8/AD8 -> 0.33398738 | AI8: =AF8/(AD8/30) -> 87.414585 | AL8: RPSPL-GUJ | AM8: 313034.52 | AN8: 145656 | AO8: 240288 | AP8: 265248 | AQ8: =AN8/AM8 -> 0.46530332 | AR8: =AO8/(AM8/30) -> 23.028259 | AU8: RPSPL-GUJ | AV8: 448.32 | AW8: 0 | AX8: 0 | AY8: 0 | AZ8: =AW8/AV8 -> 0 | BA8: =AX8/(AV8/30) -> 0
B9: RPSPL-HP Factory | C9: 0 | D9: 0 | E9: 216 | F9: 216 | G9: =D9/C9 -> #DIV/0! | H9: =E9/(C9/30) -> #DIV/0! | K9: RPSPL-HY | L9: 16050.24 | M9: 10692 | N9: 8748 | O9: 11148 | P9: =M9/L9 -> 0.66615826 | Q9: =N9/(L9/30) -> 16.351157 | T9: RPSPL-GUJ | U9: 34.56 | V9: 0 | W9: 228 | X9: 228 | Y9: =V9/U9 -> 0 | Z9: =W9/(U9/30) -> 197.91667 | AC9: RPSPL-HY | AD9: 9747.68 | AE9: 6977 | AF9: 7604 | AG9: 10121 | AH9: =AE9/AD9 -> 0.71576006 | AI9: =AF9/(AD9/30) -> 23.402492 | AL9: RPSPL-HP Factory | AM9: 31623.12 | AN9: 0 | AO9: 42136 | AP9: 42136 | AQ9: =AN9/AM9 -> 0 | AR9: =AO9/(AM9/30) -> 39.973285 | AU9: RPSPL-HY | AV9: 5362.56 | AW9: 2532 | AX9: 5460 | AY9: 5460 | AZ9: =AW9/AV9 -> 0.47216255 | BA9: =AX9/(AV9/30) -> 30.545113
B10: RPSPL-HY | C10: 52002.72 | D10: 23796 | E10: 30168 | F10: 30168 | G10: =D10/C10 -> 0.45759145 | H10: =E10/(C10/30) -> 17.403705 | K10: RPSPL-KER | L10: 3900 | M10: 2424 | N10: 4068 | O10: 5268 | P10: =M10/L10 -> 0.62153846 | Q10: =N10/(L10/30) -> 31.292308 | T10: RPSPL-HY | U10: 166.2 | V10: 12 | W10: 84 | X10: 84 | Y10: =V10/U10 -> 0.072202166 | Z10: =W10/(U10/30) -> 15.162455 | AC10: RPSPL-KER | AD10: 4579.4 | AE10: 2842 | AF10: 3230 | AG10: 4148 | AH10: =AE10/AD10 -> 0.62060532 | AI10: =AF10/(AD10/30) -> 21.159977 | AL10: RPSPL-HY | AM10: 397433.28 | AN10: 247740 | AO10: 156888 | AP10: 231012 | AQ10: =AN10/AM10 -> 0.62334991 | AR10: =AO10/(AM10/30) -> 11.842592 | AU10: RPSPL-KER | AV10: 8199.96 | AW10: 2916 | AX10: 600 | AY10: 984 | AZ10: =AW10/AV10 -> 0.35561149 | BA10: =AX10/(AV10/30) -> 2.1951327
B11: RPSPL-KER | C11: 12480.6 | D11: 5352 | E11: 3300 | F11: 3600 | G11: =D11/C11 -> 0.42882554 | H11: =E11/(C11/30) -> 7.9323109 | K11: RPSPL-KOL | L11: 10938.84 | M11: 4188 | N11: 11400 | O11: 11400 | P11: =M11/L11 -> 0.38285595 | Q11: =N11/(L11/30) -> 31.264741 | T11: RPSPL-KER | U11: 321.6 | V11: 72 | W11: 276 | X11: 276 | Y11: =V11/U11 -> 0.2238806 | Z11: =W11/(U11/30) -> 25.746269 | AC11: RPSPL-KOL | AD11: 8070.79 | AE11: 2818 | AF11: 4893 | AG11: 8007 | AH11: =AE11/AD11 -> 0.34916037 | AI11: =AF11/(AD11/30) -> 18.187811 | AL11: RPSPL-KER | AM11: 474013.76 | AN11: 316852 | AO11: 257112 | AP11: 370056 | AQ11: =AN11/AM11 -> 0.66844473 | AR11: =AO11/(AM11/30) -> 16.272439 | AU11: RPSPL-KOL | AV11: 1876.56 | AW11: 660 | AX11: 1284 | AY11: 1284 | AZ11: =AW11/AV11 -> 0.35170738 | BA11: =AX11/(AV11/30) -> 20.526922
B12: RPSPL-KOL | C12: 21877.92 | D12: 9276 | E12: 15600 | F12: 15600 | G12: =D12/C12 -> 0.42398912 | H12: =E12/(C12/30) -> 21.39143 | K12: RPSPL-MP | L12: 5950.44 | M12: 4416 | N12: 56376 | O12: 56376 | P12: =M12/L12 -> 0.74212999 | Q12: =N12/(L12/30) -> 284.22772 | T12: RPSPL-KOL | U12: 591.72 | V12: 48 | W12: 336 | X12: 336 | Y12: =V12/U12 -> 0.081119448 | Z12: =W12/(U12/30) -> 17.035084 | AC12: RPSPL-MP | AD12: 1428.84 | AE12: 702 | AF12: 39803 | AG12: 39803 | AH12: =AE12/AD12 -> 0.49130763 | AI12: =AF12/(AD12/30) -> 835.70589 | AL12: RPSPL-KOL | AM12: 325444.56 | AN12: 180900 | AO12: 166932 | AP12: 214056 | AQ12: =AN12/AM12 -> 0.55585504 | AR12: =AO12/(AM12/30) -> 15.388059 | AU12: RPSPL-MP | AV12: 1286.64 | AW12: 84 | AX12: 0 | AY12: 0 | AZ12: =AW12/AV12 -> 0.065286327 | BA12: =AX12/(AV12/30) -> 0
B13: RPSPL-MP | C13: 12722.16 | D13: 7968 | E13: 23424 | F13: 23424 | G13: =D13/C13 -> 0.62630874 | H13: =E13/(C13/30) -> 55.235903 | K13: RPSPL-NG | L13: 7713.12 | M13: 4344 | N13: 8628 | O13: 11028 | P13: =M13/L13 -> 0.56319622 | Q13: =N13/(L13/30) -> 33.558404 | T13: RPSPL-MP | U13: 206.76 | V13: 12 | W13: 180 | X13: 180 | Y13: =V13/U13 -> 0.058038305 | Z13: =W13/(U13/30) -> 26.117237 | AC13: RPSPL-NG | AD13: 4435.77 | AE13: 2762 | AF13: 4155 | AG13: 4155 | AH13: =AE13/AD13 -> 0.62266529 | AI13: =AF13/(AD13/30) -> 28.101096 | AL13: RPSPL-MP | AM13: 116829 | AN13: 80640 | AO13: 285300 | AP13: 285744 | AQ13: =AN13/AM13 -> 0.69023958 | AR13: =AO13/(AM13/30) -> 73.26092 | AU13: RPSPL-NG | AV13: 1608.36 | AW13: 1104 | AX13: 912 | AY13: 912 | AZ13: =AW13/AV13 -> 0.68641349 | BA13: =AX13/(AV13/30) -> 17.011117
B14: RPSPL-NG | C14: 13795.56 | D14: 6096 | E14: 10188 | F14: 11688 | G14: =D14/C14 -> 0.4418813 | H14: =E14/(C14/30) -> 22.154954 | K14: RPSPL-PA | L14: 17696.04 | M14: 5520 | N14: 18552 | O14: 18552 | P14: =M14/L14 -> 0.3119342 | Q14: =N14/(L14/30) -> 31.451104 | T14: RPSPL-NG | U14: 0 | V14: 36 | W14: 384 | X14: 384 | Y14: =V14/U14 -> #DIV/0! | Z14: =W14/(U14/30) -> #DIV/0! | AC14: RPSPL-PA | AD14: 4397.82 | AE14: 1800 | AF14: 5629 | AG14: 5629 | AH14: =AE14/AD14 -> 0.4092937 | AI14: =AF14/(AD14/30) -> 38.39857 | AL14: RPSPL-NG | AM14: 202313.16 | AN14: 113856 | AO14: 177900 | AP14: 200460 | AQ14: =AN14/AM14 -> 0.5627711 | AR14: =AO14/(AM14/30) -> 26.379895 | AU14: RPSPL-PA | AV14: 463.08 | AW14: 276 | AX14: 1188 | AY14: 1188 | AZ14: =AW14/AV14 -> 0.59600933 | BA14: =AX14/(AV14/30) -> 76.962944
B15: RPSPL-PA | C15: 9007.68 | D15: 6984 | E15: 12696 | F15: 12696 | G15: =D15/C15 -> 0.77533838 | H15: =E15/(C15/30) -> 42.283918 | K15: RPSPL-PBN | L15: 28982.52 | M15: 20208 | N15: 23100 | O15: 24996 | P15: =M15/L15 -> 0.69724786 | Q15: =N15/(L15/30) -> 23.910964 | T15: RPSPL-PA | U15: 578.88 | V15: 108 | W15: 84 | X15: 84 | Y15: =V15/U15 -> 0.18656716 | Z15: =W15/(U15/30) -> 4.3532338 | AC15: RPSPL-PBN | AD15: 5961 | AE15: 3890 | AF15: 7512 | AG15: 7512 | AH15: =AE15/AD15 -> 0.65257507 | AI15: =AF15/(AD15/30) -> 37.805737 | AL15: RPSPL-PA | AM15: 233005.44 | AN15: 118776 | AO15: 122736 | AP15: 146736 | AQ15: =AN15/AM15 -> 0.50975634 | AR15: =AO15/(AM15/30) -> 15.80255 | AU15: RPSPL-PBN | AV15: 2035.92 | AW15: 456 | AX15: 156 | AY15: 156 | AZ15: =AW15/AV15 -> 0.22397737 | BA15: =AX15/(AV15/30) -> 2.2987151
B16: RPSPL-PBN | C16: 30599.88 | D16: 12360 | E16: 9948 | F16: 9948 | G16: =D16/C16 -> 0.40392315 | H16: =E16/(C16/30) -> 9.7529794 | K16: RPSPL-PC | L16: 30298.8 | M16: 16176 | N16: 23952 | O16: 28776 | P16: =M16/L16 -> 0.53388253 | Q16: =N16/(L16/30) -> 23.715791 | T16: RPSPL-PBN | U16: 72 | V16: 96 | W16: 168 | X16: 168 | Y16: =V16/U16 -> 1.3333333 | Z16: =W16/(U16/30) -> 70 | AC16: RPSPL-PC | AD16: 14170.13 | AE16: 9647 | AF16: 3237 | AG16: 3237 | AH16: =AE16/AD16 -> 0.68079827 | AI16: =AF16/(AD16/30) -> 6.8531481 | AL16: RPSPL-PBN | AM16: 442332 | AN16: 286344 | AO16: 617592 | AP16: 650772 | AQ16: =AN16/AM16 -> 0.64735086 | AR16: =AO16/(AM16/30) -> 41.886547 | AU16: RPSPL-PC | AV16: 6194.88 | AW16: 3924 | AX16: 8652 | AY16: 8652 | AZ16: =AW16/AV16 -> 0.63342631 | BA16: =AX16/(AV16/30) -> 41.899117
... B20: RPSPL-Sonipat | C20: 31271.76 | D20: 24420 | E20: 9912 | F20: 20988 | G20: =D20/C20 -> 0.78089625 | H20: =E20/(C20/30) -> 9.5088988 | K20: Grand Total | L20: 252703.92 | M20: 141564 | N20: 282492 | O20: 297612 | P20: =M20/L20 -> 0.56019709 | Q20: =N20/(L20/30) -> 33.536322 | T20: RPSPL-Sonipat | U20: 312 | V20: 1716 | W20: 576 | X20: 576 | Y20: =V20/U20 -> 5.5 | Z20: =W20/(U20/30) -> 55.384615 | AC20: Grand Total | AD20: 86200.95 | AE20: 50840 | AF20: 113671 | AG20: 121825 | AH20: =AE20/AD20 -> 0.58978468 | AI20: =AF20/(AD20/30) -> 39.560237 | AL20: RPSPL-KH | AM20: 0 | AN20: 0 | AO20: 0 | AP20: 0 | AQ20: =AN20/AM20 -> #DIV/0! | AR20: =AO20/(AM20/30) -> #DIV/0! | AU20: Grand Total | AV20: 43052.04 | AW20: 20928 | AX20: 27480 | AY20: 28294 | AZ20: =AW20/AV20 -> 0.48610937 | BA20: =AX20/(AV20/30) -> 19.148918
B21: Grand Total | C21: 436307.4 | D21: 219036 | E21: 234396 | F21: 258348 | P21: =M21/L21 -> #DIV/0! | Q21: =N21/(L21/30) -> #DIV/0! | T21: Grand Total | U21: 4669.2 | V21: 2736 | W21: 5988 | X21: 5988 | AL21: RPSPL-Sonipat | AM21: 497075.04 | AN21: 313116 | AO21: 244140 | AP21: 268140 | AQ21: =AN21/AM21 -> 0.62991696 | AR21: =AO21/(AM21/30) -> 14.734596
AL22: Grand Total | AM22: 5417188.4 | AN22: 3107580 | AO22: 3764366 | AP22: 4484438 | AQ22: =AN22/AM22 -> 0.57365182 | AR22: =AO22/(AM22/30) -> 20.846788

Sheet Master
A1: Plant | B1: Plant Name | C1: Material Code | D1: Group | E1: Material Description | F1: Cat | G1: Source | H1: Source as per VP | K1: Plant | L1: Hub's | M1: Plant Name | N1: 1000 | O1: RPSPL-PuneFactory | W1: T&I Comm -HP
A2: 4106 | B2: RPSPL-KH | C2: 01296 | D2: 410601296 | E2: Rich’s Cremagic - 2 Kg | F2: T&I | G2: T&I EX HP 2 KG | H2: T&I EX HP 2 KG | K2: 1000 | L2: Pune | M2: RPSPL-PuneFactory | N2: 2000 | O2: RPSPL-HPFactory | W2: T&I EX HP
A3: 2000 | B3: RPSPL-HP Factory | C3: 01296 | D3: 200001296 | E3: Rich’s Cremagic - 2 Kg | F3: T&I | G3: T&I EX HP 2 KG | H3: T&I EX HP 2 KG | K3: 1110 | L3: RMPM/Kuruli | M3: #N/A | N3: 3500 | O3: RPSPL-BNT-BangaloreTAC | W3: T&I Comm-PF
A4: 2000 | B4: RPSPL-HP Factory | C4: 02122 | D4: 200002122 | E4: Rich's Dairy Free Whip Topping - 2 Kg | F4: T&I | G4: T&I EX HP 2 KG | H4: T&I EX HP 2 KG | K4: 1200 | L4: R&D | M4: #N/A | N4: 4100 | O4: RPSPL-GUJ | W4: T&I common -HP 2 KG
A5: 2000 | B5: RPSPL-HP Factory | C5: 07310 | D5: 200007310 | E5: Rich's Cooking Rich Hot Kitchen Appl. | F5: T&I | G5: T&I Comm -HP | H5: Common T&I | K5: 2000 | L5: HP | M5: RPSPL-HP Factory | N5: 4101 | O5: RPSPL-PC | W5: OS - Dry
A6: 2000 | B6: RPSPL-HP Factory | C6: 08529 | D6: 200008529 | E6: Rich's Truffle Base | F6: T&I | G6: T&I EX HP 2 KG | H6: T&I EX HP 2 KG | K6: 3500 | L6: BNT-Bangalore TAC | M6: #N/A | N6: 4102 | O6: RPSPL-MP | W6: OS-Chill
A7: 2000 | B7: RPSPL-HP Factory | C7: 13179 | D7: 200013179 | E7: Rich’s Whip Topping Gold (India) | F7: T&I | G7: T&I EX HP 2 KG | H7: T&I EX HP 2 KG | K7: 4100 | L7: AH | M7: #N/A | N7: 4104 | O7: RPSPL-RJ | W7: PF-Dry
A8: 2000 | B8: RPSPL-HP Factory | C8: 22754 | D8: 200022754 | E8: RWT - Cheese Flavoured (1 kg) | F8: T&I | G8: T&I EX HP | H8: T&I EX HP | K8: 4101 | L8: PC | M8: RPSPL-PC | N8: 4105 | O8: RPSPL-NG | W8: T&I EX PF
A9: 2000 | B9: RPSPL-HP Factory | C9: 23691 | D9: 200023691 | E9: RICH'S WT Gold 1 Kg (Middle East) | F9: T&I | G9: T&I EX HP | H9: T&I EX HP | K9: 4102 | L9: MP | M9: #N/A | N9: 4200 | O9: RPSPL-KOL | W9: T&I common -PF 2 KG
A10: 4100 | B10: RPSPL-GUJ | C10: 06151 | D10: 410006151 | E10: Rich's Double Dream | F10: DD | G10: OS - Dry | H10: Comman | K10: 4104 | L10: JP | M10: #N/A | N10: 4201 | O10: RPSPL-GT | W10: Ganache- PF
A11: 4100 | B11: RPSPL-GUJ | C11: 19690 | D11: 410019690 | E11: Rich's Nufill Blueberry FruitFilling 1Kg | F11: NFL | G11: OS - Dry | H11: Comman | K11: 4105 | L11: NG | M11: #N/A | N11: 4203 | O11: RPSPL-PA
A12: 4100 | B12: RPSPL-GUJ | C12: 20160 | D12: 410020160 | E12: RICH'S NUFILL DARK CHERRY FRUIT FILLING | F12: NFL | G12: OS - Dry | H12: Comman | K12: 4200 | L12: KL | M12: #N/A | N12: 4300 | O12: RPSPL-DEL
A13: 4100 | B13: RPSPL-GUJ | C13: 20661 | D13: 410020661 | E13: Rich’s Wilber Farms Dairy Cream 1ltr | F13: UHT-Chill | G13: OS-Chill | H13: Comman | K13: 4201 | L13: GT | M13: #N/A | N13: 4301 | O13: RPSPL-PBN
A14: 4100 | B14: RPSPL-GUJ | C14: 23638 | D14: 410023638 | E14: Rich's Versatie Gold- Cooking Base 1 ltr | F14: DD | G14: OS - Dry | H14: Comman | K14: 4203 | L14: PA | M14: #N/A | N14: 4302 | O14: RPSPL-KNP
A15: 4100 | B15: RPSPL-GUJ | C15: 04145 | D15: 410004145 | E15: Rich's Nugel Caramel (1 Kg) | F15: NGL | G15: UF-Dry | H15: DRY NGL+DD | K15: 4300 | L15: DL | M15: #N/A | N15: 4400 | O15: RPSPL-CH
A16: 4100 | B16: RPSPL-GUJ | C16: 13490 | D16: 410013490 | E16: Rich's Nugel Neutral Glaze 2.5 Kg IN | F16: NGL | G16: UF-Dry | H16: DRY NGL+DD | K16: 4301 | L16: PBN | M16: RPSPL-PBN | N16: 4401 | O16: RPSPL-BNG
A17: 4100 | B17: RPSPL-GUJ | C17: 14248 | D17: 410014248 | E17: Rich's Nugel Cocoa Glaze 2.5 Kg (India) | F17: NGL | G17: UF-Dry | H17: DRY NGL+DD | K17: 4302 | L17: KN | M17: #N/A | N17: 4403 | O17: RPSPL-HY
A18: 4100 | B18: RPSPL-GUJ | C18: 15300 | D18: 410015300 | E18: Rich's Nugel Pineapple Glaze 1.0 Kg IN | F18: NGL | G18: UF-Dry | H18: DRY NGL+DD | K18: 4400 | L18: CH | M18: #N/A | N18: 4404 | O18: RPSPL-KER
A19: 4100 | B19: RPSPL-GUJ | C19: 15305 | D19: 410015305 | E19: Rich's Nugel Strawberry Glaze 1.0 Kg IN | F19: NGL | G19: UF-Dry | H19: DRY NGL+DD | K19: 4401 | L19: BN | M19: #N/A
A20: 4100 | B20: RPSPL-GUJ | C20: 15312 | D20: 410015312 | E20: Rich's Nugel Blueberry Glaze 1.0 Kg IN | F20: NGL | G20: UF-Dry | H20: DRY NGL+DD | K20: 4403 | L20: HY | M20: RPSPL-HY
A21: 4100 | B21: RPSPL-GUJ | C21: 16407 | D21: 410016407 | E21: Rich's Nugel White 1 Kg (India) | F21: NGL | G21: UF-Dry | H21: DRY NGL+DD | K21: 4404 | L21: KO | M21: #N/A
A22: 4100 | B22: RPSPL-GUJ | C22: 00189 | D22: 410000189 | E22: Rich's New Star Whip 1 Kg | F22: T&I | G22: T&I Comm-UF | H22: Common T&I | K22: 5000 | L22: Ujjain | M22: #N/A
A23: 4100 | B23: RPSPL-GUJ | C23: 01167 | D23: 410001167 | E23: Rich's Sweetmate (India) 1 Kg | F23: T&I | G23: T&I EX UF | H23: T&I EX UF | K23: 4106 | L23: KHA | M23: RPSPL-KH
A24: 4100 | B24: RPSPL-GUJ | C24: 01296 | D24: 410001296 | E24: Rich’s Cremagic - 2 Kg | F24: T&I | G24: T&I EX HP 2 KG | H24: T&I EX HP 2 KG | K24: 2000 | L24: HP
A25: 4100 | B25: RPSPL-GUJ | C25: 02122 | D25: 410002122 | E25: Rich's Dairy Free Whip Topping - 2 Kg | F25: T&I | G25: T&I EX HP 2 KG | H25: T&I EX HP 2 KG
A26: 4100 | B26: RPSPL-GUJ | C26: 05159 | D26: 410005159 | E26: Rich's Whip Topping-Gold 500 G (India) | F26: T&I | G26: T&I EX HP | H26: T&I EX HP
A27: 4100 | B27: RPSPL-GUJ | C27: 06982 | D27: 410006982 | E27: Rich's Chocolate Whip Topping | F27: T&I | G27: T&I Comm-UF | H27: Common T&I
A28: 4100 | B28: RPSPL-GUJ | C28: 07310 | D28: 410007310 | E28: Rich's Cooking Rich Hot Kitchen Appl. | F28: T&I | G28: T&I Comm-UF | H28: Common T&I
A29: 4100 | B29: RPSPL-GUJ | C29: 08529 | D29: 410008529 | E29: Rich's Truffle Base | F29: T&I | G29: T&I EX HP 2 KG | H29: T&I EX HP 2 KG
A30: 4100 | B30: RPSPL-GUJ | C30: 13179 | D30: 410013179 | E30: Rich’s Whip Topping Gold (India) | F30: T&I | G30: T&I EX HP 2 KG | H30: T&I EX HP 2 KG
A31: 4100 | B31: RPSPL-GUJ | C31: 13678 | D31: 410013678 | E31: Rich’s New Niagara Farms | F31: T&I | G31: T&I EX HP | H31: T&I EX HP
A32: 4100 | B32: RPSPL-GUJ | C32: 14654 | D32: 410014654 | E32: Rich's Bettercreme | F32: T&I | G32: T&I Comm-UF | H32: Common T&I
A33: 4100 | B33: RPSPL-GUJ | C33: 14788 | D33: 410014788 | E33: Rich’s Whip Topping-Gold 1 Kg | F33: T&I | G33: T&I EX HP | H33: T&I EX HP
A34: 4100 | B34: RPSPL-GUJ | C34: 15536 | D34: 410015536 | E34: Rich's Premium Truffle -2 Kg | F34: Ganache | G34: Ganache- UF | H34: UF Exclusive
A35: 4100 | B35: RPSPL-GUJ | C35: 15906 | D35: 410015906 | E35: Rich’s Whip Topping (India) 1 Kg | F35: T&I | G35: T&I EX HP | H35: T&I EX HP
A36: 4100 | B36: RPSPL-GUJ | C36: 16336 | D36: 410016336 | E36: Sunwhip (India) 1 Kg | F36: T&I | G36: T&I Comm-UF | H36: Common T&I
... A75: 4101 | B75: RPSPL-PC | C75: 14788 | D75: 410114788 | E75: Rich’s Whip Topping-Gold 1 Kg | F75: T&I | G75: T&I EX HP | H75: T&I EX HP
A76: 4101 | B76: RPSPL-PC | C76: 15459 | D76: 410115459 | E76: Rich's Cooking Rich-Hot Kitchen (10 Kg) | F76: T&I | G76: T&I EX HP | H76: T&I EX HP
A77: 4101 | B77: RPSPL-PC | C77: 15536 | D77: 410115536 | E77: Rich's Premium Truffle -2 Kg | F77: Ganache | G77: Ganache- UF | H77: UF Exclusive
A78: 4101 | B78: RPSPL-PC | C78: 15906 | D78: 410115906 | E78: Rich’s Whip Topping (India) 1 Kg | F78: T&I | G78: T&I EX HP | H78: T&I EX HP
...

Sheet BAse
J1: =SUM(J3:J1048576) -> 3542684
A2: Group | B2: Plant | C2: Plant Name | D2: Material Code | E2: Group | F2: Material Description | G2: Cat | H2: Source | I2: RF May- 26 | J2: Sales Qty | K2: % With Forecast | L2: Transit | M2: Ship Date | N2: Ready Stock | O2: Ready + transist | P2: RF Pendency | Q2: INV Days R+T | R2: INV Days (Ready Stock) | T2: =TODAY()-1 -> 46166 | U2: =TEXT($T$2,"dd") -> 24 | V2: =U2/30 -> 0.8 | W2: =V2-10% -> 0.7 | X2: =V2+10% -> 0.9
A3: =B3&D3 -> 430019690 | B3: 4300 | C3: =_xlfn.XLOOKUP(B:B,Master!A:A,Master!B:B) -> RPSPL-DEL | D3: 19690 | E3: =B3&D3 -> 430019690 | F3: Rich's Nufill Blueberry FruitFilling 1Kg | G3: =VLOOKUP(D3,Master!C:G,4,) -> NFL | H3: =VLOOKUP(D3,Master!C:G,5,) -> OS - Dry | I3: 0 | J3: 0 | K3: =IFERROR(J3/I3,0) -> 0 | L3: 0 | N3: 0 | O3: =N3+L3 -> 0 | P3: =I3-J3-O3 -> 0 | Q3: =IFERROR(IF(D3=20250,O3/(#REF!/30),O3/(I3/30)),0) -> 0 | R3: =IFERROR(N3/(I3/30),0) -> 0
A4: =B4&D4 -> 410600189 | B4: 4106 | C4: =_xlfn.XLOOKUP(B:B,Master!A:A,Master!B:B) -> RPSPL-KH | D4: 00189 | E4: =B4&D4 -> 410600189 | F4: Rich's Star Whip 1 Kg | G4: =VLOOKUP(D4,Master!C:G,4,) -> T&I | H4: =VLOOKUP(D4,Master!C:G,5,) -> T&I Comm-UF | I4: 0 | J4: 0 | K4: =IFERROR(J4/I4,0) -> 0 | L4: 0 | N4: 0 | O4: =N4+L4 -> 0 | P4: =I4-J4-O4 -> 0 | Q4: =IFERROR(IF(D4=20250,O4/(#REF!/30),O4/(I4/30)),0) -> 0 | R4: =IFERROR(N4/(I4/30),0) -> 0
A5: =B5&D5 -> 200000189 | B5: 2000 | C5: =_xlfn.XLOOKUP(B:B,Master!A:A,Master!B:B) -> RPSPL-HP Factory | D5: 00189 | E5: =B5&D5 -> 200000189 | F5: Rich's Star Whip 1 Kg | G5: =VLOOKUP(D5,Master!C:G,4,) -> T&I | H5: =VLOOKUP(D5,Master!C:G,5,) -> T&I Comm-UF | I5: 6478.08 | J5: 0 | K5: =IFERROR(J5/I5,0) -> 0 | L5: 0 | N5: 1212 | O5: 1212 | P5: =I5-J5-O5 -> 5266.08 | Q5: =IFERROR(IF(D5=20250,O5/(#REF!/30),O5/(I5/30)),0) -> 5.6127742 | R5: =IFERROR(N5/(I5/30),0) -> 5.6127742
A6: =B6&D6 -> 200001296 | B6: 2000 | C6: =_xlfn.XLOOKUP(B:B,Master!A:A,Master!B:B) -> RPSPL-HP Factory | D6: 01296 | E6: =B6&D6 -> 200001296 | F6: Rich’s Cremagic - 2 Kg | G6: =VLOOKUP(D6,Master!C:G,4,) -> T&I | H6: =VLOOKUP(D6,Master!C:G,5,) -> T&I EX HP 2 KG | I6: 550.2 | J6: 0 | K6: =IFERROR(J6/I6,0) -> 0 | L6: 0 | N6: 0 | O6: 0 | P6: =I6-J6-O6 -> 550.2 | Q6: =IFERROR(IF(D6=20250,O6/(#REF!/30),O6/(I6/30)),0) -> 0 | R6: =IFERROR(N6/(I6/30),0) -> 0
A7: =B7&D7 -> 200002122 | B7: 2000 | C7: =_xlfn.XLOOKUP(B:B,Master!A:A,Master!B:B) -> RPSPL-HP Factory | D7: 02122 | E7: =B7&D7 -> 200002122 | F7: Rich's Dairy Free Whip Topping - 2 Kg | G7: =VLOOKUP(D7,Master!C:G,4,) -> T&I | H7: =VLOOKUP(D7,Master!C:G,5,) -> T&I EX HP 2 KG | I7: 1122.36 | J7: 0 | K7: =IFERROR(J7/I7,0) -> 0 | L7: 0 | N7: 1068 | O7: 1068 | P7: =I7-J7-O7 -> 54.36 | Q7: =IFERROR(IF(D7=20250,O7/(#REF!/30),O7/(I7/30)),0) -> 28.54699 | R7: =IFERROR(N7/(I7/30),0) -> 28.54699
A8: =B8&D8 -> 200005159 | B8: 2000 | C8: =_xlfn.XLOOKUP(B:B,Master!A:A,Master!B:B) -> RPSPL-HP Factory | D8: 05159 | E8: =B8&D8 -> 200005159 | F8: Rich's Whip Topping-Gold 500 G (India) | G8: =VLOOKUP(D8,Master!C:G,4,) -> T&I | H8: =VLOOKUP(D8,Master!C:G,5,) -> T&I EX HP | I8: 0 | J8: 0 | K8: =IFERROR(J8/I8,0) -> 0 | L8: 0 | N8: 3624 | O8: 3624 | P8: =I8-J8-O8 -> -3624 | Q8: =IFERROR(IF(D8=20250,O8/(#REF!/30),O8/(I8/30)),0) -> 0 | R8: =IFERROR(N8/(I8/30),0) -> 0
A9: =B9&D9 -> 200007310 | B9: 2000 | C9: =_xlfn.XLOOKUP(B:B,Master!A:A,Master!B:B) -> RPSPL-HP Factory | D9: 07310 | E9: =B9&D9 -> 200007310 | F9: Rich's Cooking Rich Hot Kitchen Appl. | G9: =VLOOKUP(D9,Master!C:G,4,) -> T&I | H9: =VLOOKUP(D9,Master!C:G,5,) -> T&I Comm -HP | I9: 6678.96 | J9: 0 | K9: =IFERROR(J9/I9,0) -> 0 | L9: 0 | N9: 1152 | O9: 1152 | P9: =I9-J9-O9 -> 5526.96 | Q9: =IFERROR(IF(D9=20250,O9/(#REF!/30),O9/(I9/30)),0) -> 5.1744583 | R9: =IFERROR(N9/(I9/30),0) -> 5.1744583
A10: =B10&D10 -> 200008529 | B10: 2000 | C10: =_xlfn.XLOOKUP(B:B,Master!A:A,Master!B:B) -> RPSPL-HP Factory | D10: 08529 | E10: =B10&D10 -> 200008529 | F10: Rich's Truffle Base | G10: =VLOOKUP(D10,Master!C:G,4,) -> T&I | H10: =VLOOKUP(D10,Master!C:G,5,) -> T&I EX HP 2 KG | I10: 0 | J10: 0 | K10: =IFERROR(J10/I10,0) -> 0 | L10: 0 | N10: 2172 | O10: 2172 | P10: =I10-J10-O10 -> -2172 | Q10: =IFERROR(IF(D10=20250,O10/(#REF!/30),O10/(I10/30)),0) -> 0 | R10: =IFERROR(N10/(I10/30),0) -> 0
A11: =B11&D11 -> 200013179 | B11: 2000 | C11: =_xlfn.XLOOKUP(B:B,Master!A:A,Master!B:B) -> RPSPL-HP Factory | D11: 13179 | E11: =B11&D11 -> 200013179 | F11: Rich’s Whip Topping Gold (India) | G11: =VLOOKUP(D11,Master!C:G,4,) -> T&I | H11: =VLOOKUP(D11,Master!C:G,5,) -> T&I EX HP 2 KG | I11: 15129.72 | J11: 0 | K11: =IFERROR(J11/I11,0) -> 0 | L11: 0 | N11: 31644 | O11: 31644 | P11: =I11-J11-O11 -> -16514.28 | Q11: =IFERROR(IF(D11=20250,O11/(#REF!/30),O11/(I11/30)),0) -> 62.745378 | R11: =IFERROR(N11/(I11/30),0) -> 62.745378
A12: =B12&D12 -> 200013678 | B12: 2000 | C12: =_xlfn.XLOOKUP(B:B,Master!A:A,Master!B:B) -> RPSPL-HP Factory | D12: 13678 | E12: =B12&D12 -> 200013678 | F12: Rich’s New Niagara Farms | G12: =VLOOKUP(D12,Master!C:G,4,) -> T&I | H12: =VLOOKUP(D12,Master!C:G,5,) -> T&I EX HP | I12: 0 | J12: 0 | K12: =IFERROR(J12/I12,0) -> 0 | L12: 0 | N12: 48 | O12: 48 | P12: =I12-J12-O12 -> -48 | Q12: =IFERROR(IF(D12=20250,O12/(#REF!/30),O12/(I12/30)),0) -> 0 | R12: =IFERROR(N12/(I12/30),0) -> 0
A13: =B13&D13 -> 200014654 | B13: 2000 | C13: =_xlfn.XLOOKUP(B:B,Master!A:A,Master!B:B) -> RPSPL-HP Factory | D13: 14654 | E13: =B13&D13 -> 200014654 | F13: Rich's Bettercreme | G13: =VLOOKUP(D13,Master!C:G,4,) -> T&I | H13: =VLOOKUP(D13,Master!C:G,5,) -> T&I Comm-UF | I13: 0 | J13: 0 | K13: =IFERROR(J13/I13,0) -> 0 | L13: 0 | N13: 36 | O13: 36 | P13: =I13-J13-O13 -> -36 | Q13: =IFERROR(IF(D13=20250,O13/(#REF!/30),O13/(I13/30)),0) -> 0 | R13: =IFERROR(N13/(I13/30),0) -> 0
